<sdf version='1.7'>
  <world name='default'>
    <light name='sun' type='directional'>
      <cast_shadows>1</cast_shadows>
      <pose>0 0 10 0 -0 0</pose>
      <diffuse>0.8 0.8 0.8 1</diffuse>
      <specular>0.2 0.2 0.2 1</specular>
      <attenuation>
        <range>1000</range>
        <constant>0.9</constant>
        <linear>0.01</linear>
        <quadratic>0.001</quadratic>
      </attenuation>
      <direction>-0.5 0.1 -0.9</direction>
      <spot>
        <inner_angle>0</inner_angle>
        <outer_angle>0</outer_angle>
        <falloff>0</falloff>
      </spot>
    </light>
    <model name='ground_plane'>
      <static>1</static>
      <link name='link'>
        <collision name='collision'>
          <geometry>
            <plane>
              <normal>0 0 1</normal>
              <size>100 100</size>
            </plane>
          </geometry>
          <surface>
            <friction>
              <ode>
                <mu>100</mu>
                <mu2>50</mu2>
              </ode>
              <torsional>
                <ode/>
              </torsional>
            </friction>
            <contact>
              <ode/>
            </contact>
            <bounce/>
          </surface>
          <max_contacts>10</max_contacts>
        </collision>
        <visual name='visual'>
          <cast_shadows>0</cast_shadows>
          <geometry>
            <plane>
              <normal>0 0 1</normal>
              <size>100 100</size>
            </plane>
          </geometry>
          <material>
            <script>
              <uri>file://media/materials/scripts/gazebo.material</uri>
              <name>Gazebo/Grey</name>
            </script>
          </material>
        </visual>
        <self_collide>0</self_collide>
        <enable_wind>0</enable_wind>
        <kinematic>0</kinematic>
      </link>
    </model>
    <gravity>0 0 -9.8</gravity>
    <magnetic_field>6e-06 2.3e-05 -4.2e-05</magnetic_field>
    <atmosphere type='adiabatic'/>
    <physics type='ode'>
      <max_step_size>0.001</max_step_size>
      <real_time_factor>1</real_time_factor>
      <real_time_update_rate>1000</real_time_update_rate>
    </physics>
    <scene>
      <ambient>0.4 0.4 0.4 1</ambient>
      <background>0.7 0.7 0.7 1</background>
      <shadows>1</shadows>
    </scene>
    <wind/>
    <spherical_coordinates>
      <surface_model>EARTH_WGS84</surface_model>
      <latitude_deg>0</latitude_deg>
      <longitude_deg>0</longitude_deg>
      <elevation>0</elevation>
      <heading_deg>0</heading_deg>
    </spherical_coordinates>
    <model name='unit_cylinder_mass_1'>
      <pose>-0.04258 4.16223 0.5 0 -0 0</pose>
      <link name='link'>
        <inertial>
          <mass>1</mass>
          <inertia>
            <ixx>0.145833</ixx>
            <ixy>0</ixy>
            <ixz>0</ixz>
            <iyy>0.145833</iyy>
            <iyz>0</iyz>
            <izz>0.125</izz>
          </inertia>
          <pose>0 0 0 0 -0 0</pose>
        </inertial>
        <collision name='collision'>
          <geometry>
            <cylinder>
              <radius>0.500002</radius>
              <length>1</length>
            </cylinder>
          </geometry>
          <max_contacts>10</max_contacts>
          <surface>
            <contact>
              <ode/>
            </contact>
            <bounce/>
            <friction>
              <torsional>
                <ode/>
              </torsional>
              <ode/>
            </friction>
          </surface>
        </collision>
        <visual name='visual'>
          <geometry>
            <cylinder>
              <radius>0.500002</radius>
              <length>1</length>
            </cylinder>
          </geometry>
          <material>
            <script>
              <name>Gazebo/Grey</name>
              <uri>file://media/materials/scripts/gazebo.material</uri>
            </script>
          </material>
        </visual>
        <self_collide>0</self_collide>
        <enable_wind>0</enable_wind>
        <kinematic>0</kinematic>
      </link>
    </model>
    <model name='unit_cylinder_mass_3'>
      <pose>-0.036143 4.84107 0.093203 3.14159 1.57079 3.14159</pose>
      <link name='link'>
        <inertial>
          <mass>3</mass>
          <inertia>
            <ixx>0.145833</ixx>
            <ixy>0</ixy>
            <ixz>0</ixz>
            <iyy>0.145833</iyy>
            <iyz>0</iyz>
            <izz>0.125</izz>
          </inertia>
          <pose>0 0 0 0 -0 0</pose>
        </inertial>
        <collision name='collision'>
          <geometry>
            <cylinder>
              <radius>0.093203</radius>
              <length>1.48809</length>
            </cylinder>
          </geometry>
          <max_contacts>10</max_contacts>
          <surface>
            <contact>
              <ode/>
            </contact>
            <bounce/>
            <friction>
              <torsional>
                <ode/>
              </torsional>
              <ode/>
            </friction>
          </surface>
        </collision>
        <visual name='visual'>
          <geometry>
            <cylinder>
              <radius>0.093203</radius>
              <length>1.48809</length>
            </cylinder>
          </geometry>
          <material>
            <script>
              <name>Gazebo/Grey</name>
              <uri>file://media/materials/scripts/gazebo.material</uri>
            </script>
          </material>
        </visual>
        <self_collide>0</self_collide>
        <enable_wind>0</enable_wind>
        <kinematic>0</kinematic>
      </link>
    </model>
    <model name='unit_cylinder_mass_5'>
      <pose>-0.012498 5.45343 0.093203 3.14159 1.57079 3.14159</pose>
      <link name='link'>
        <inertial>
          <mass>5</mass>
          <inertia>
            <ixx>0.145833</ixx>
            <ixy>0</ixy>
            <ixz>0</ixz>
            <iyy>0.145833</iyy>
            <iyz>0</iyz>
            <izz>0.125</izz>
          </inertia>
          <pose>0 0 0 0 -0 0</pose>
        </inertial>
        <collision name='collision'>
          <geometry>
            <cylinder>
              <radius>0.093203</radius>
              <length>1.48809</length>
            </cylinder>
          </geometry>
          <max_contacts>10</max_contacts>
          <surface>
            <contact>
              <ode/>
            </contact>
            <bounce/>
            <friction>
              <torsional>
                <ode/>
              </torsional>
              <ode/>
            </friction>
          </surface>
        </collision>
        <visual name='visual'>
          <geometry>
            <cylinder>
              <radius>0.093203</radius>
              <length>1.48809</length>
            </cylinder>
          </geometry>
          <material>
            <script>
              <name>Gazebo/Grey</name>
              <uri>file://media/materials/scripts/gazebo.material</uri>
            </script>
          </material>
        </visual>
        <self_collide>0</self_collide>
        <enable_wind>0</enable_wind>
        <kinematic>0</kinematic>
      </link>
    </model>
    <model name='unit_cylinder_mass_10'>
      <pose>-0.048771 6.11003 0.093203 3.14159 1.57079 3.14159</pose>
      <link name='link'>
        <inertial>
          <mass>10</mass>
          <inertia>
            <ixx>0.145833</ixx>
            <ixy>0</ixy>
            <ixz>0</ixz>
            <iyy>0.145833</iyy>
            <iyz>0</iyz>
            <izz>0.125</izz>
          </inertia>
          <pose>0 0 0 0 -0 0</pose>
        </inertial>
        <collision name='collision'>
          <geometry>
            <cylinder>
              <radius>0.093203</radius>
              <length>1.48809</length>
            </cylinder>
          </geometry>
          <max_contacts>10</max_contacts>
          <surface>
            <contact>
              <ode/>
            </contact>
            <bounce/>
            <friction>
              <torsional>
                <ode/>
              </torsional>
              <ode/>
            </friction>
          </surface>
        </collision>
        <visual name='visual'>
          <geometry>
            <cylinder>
              <radius>0.093203</radius>
              <length>1.48809</length>
            </cylinder>
          </geometry>
          <material>
            <script>
              <name>Gazebo/Grey</name>
              <uri>file://media/materials/scripts/gazebo.material</uri>
            </script>
          </material>
        </visual>
        <self_collide>0</self_collide>
        <enable_wind>0</enable_wind>
        <kinematic>0</kinematic>
      </link>
    </model>
    <state world_name='default'>
      <sim_time>152 247000000</sim_time>
      <real_time>61 978836083</real_time>
      <wall_time>1639846617 124467752</wall_time>
      <iterations>60867</iterations>
      <model name='ground_plane'>
        <pose>0 0 0 0 -0 0</pose>
        <scale>1 1 1</scale>
        <link name='link'>
          <pose>0 0 0 0 -0 0</pose>
          <velocity>0 0 0 0 -0 0</velocity>
          <acceleration>0 0 0 0 -0 0</acceleration>
          <wrench>0 0 0 0 -0 0</wrench>
        </link>
      </model>
      <model name='robot'>
        <pose>0 0 0.05 0 -0 0</pose>
        <scale>1 1 1</scale>
        <link name='arm1'>
          <pose>0 -0 0.31 3e-06 -0 0</pose>
          <velocity>-0 -0 -0 0 -0 0</velocity>
          <acceleration>2e-06 2.1e-05 1e-05 -7.8e-05 7e-06 -0</acceleration>
          <wrench>1e-06 1e-05 5e-06 0 -0 0</wrench>
        </link>
        <link name='arm2'>
          <pose>0 0.049994 1.31 -2e-06 0 0</pose>
          <velocity>-0 -0 -0 -0 -0 -0</velocity>
          <acceleration>8e-06 -4.9e-05 1.5e-05 1.5e-05 1e-05 0</acceleration>
          <wrench>4e-06 -2.4e-05 8e-06 0 -0 0</wrench>
        </link>
        <link name='arm3'>
          <pose>0 0.050017 2.31 -2.3e-05 2e-06 -0</pose>
          <velocity>-0 0 -0 -0 -0 -0</velocity>
          <acceleration>1.8e-05 -8e-06 1.5e-05 -0.000105 1.2e-05 0</acceleration>
          <wrench>9e-06 -4e-06 8e-06 0 -0 0</wrench>
        </link>
        <link name='gripper1'>
          <pose>1e-06 2.4e-05 2.81 0.006409 2e-06 0</pose>
          <velocity>-0 0 -0 -0 -0 -0</velocity>
          <acceleration>2.5e-05 8.1e-05 2.5e-05 -0.000236 1.4e-05 0</acceleration>
          <wrench>2e-06 8e-06 2e-06 0 -0 0</wrench>
        </link>
        <link name='gripper2'>
          <pose>1e-06 2.9e-05 2.81 -2.3e-05 2e-06 -0</pose>
          <velocity>-0 0 -0 -0 -0 -0</velocity>
          <acceleration>2.4e-05 4.9e-05 2.1e-05 -0.000124 1.2e-05 -0</acceleration>
          <wrench>2e-06 5e-06 2e-06 0 -0 0</wrench>
        </link>
        <link name='spin_base'>
          <pose>0 0 0.11 0 -0 0</pose>
          <velocity>-0 -0 -0 0 -0 0</velocity>
          <acceleration>0 6e-06 1e-05 -7.5e-05 6e-06 0</acceleration>
          <wrench>1e-06 1.2e-05 2.1e-05 0 -0 0</wrench>
        </link>
        <link name='stationary_base'>
          <pose>0 0 0.05 0 -0 0</pose>
          <velocity>-0 -0 -0 0 -0 0</velocity>
          <acceleration>0 4e-06 1.1e-05 -7.3e-05 6e-06 0</acceleration>
          <wrench>3e-06 3.6e-05 0.000105 0 -0 0</wrench>
        </link>
      </model>
      <model name='unit_cylinder_mass_1'>
        <pose>-0.03162 4.16223 0.100093 3.14159 1.57079 3.14159</pose>
        <scale>0.200185 0.200185 1.3989</scale>
        <link name='link'>
          <pose>-0.03162 4.16223 0.100093 3.14159 1.57079 3.14159</pose>
          <velocity>0 0 0 0 -0 0</velocity>
          <acceleration>-0 0 0 -0 -0 -0</acceleration>
          <wrench>-0 0 0 0 -0 0</wrench>
        </link>
      </model>
      <model name='unit_cylinder_mass_10'>
        <pose>-0.04885 6.11003 0.090613 0 1.56731 0</pose>
        <scale>1 1 1</scale>
        <link name='link'>
          <pose>-0.04885 6.11003 0.090613 0 1.56731 0</pose>
          <velocity>-0.0049 0 -0.151909 0 -0.217702 0</velocity>
          <acceleration>-9.8 -0 -0 3.14159 -1.27709 3.14159</acceleration>
          <wrench>-98 -0 -0 0 -0 0</wrench>
        </link>
      </model>
      <model name='unit_cylinder_mass_3'>
        <pose>-0.036165 4.84107 0.092985 0 1.5705 0</pose>
        <scale>1 1 1</scale>
        <link name='link'>
          <pose>-0.036165 4.84107 0.092985 0 1.5705 0</pose>
          <velocity>0 0 0 0 -0 0</velocity>
          <acceleration>-9.8 -0 -0 0 0.786202 0</acceleration>
          <wrench>-29.4 -0 -0 0 -0 0</wrench>
        </link>
      </model>
      <model name='unit_cylinder_mass_5'>
        <pose>-0.012537 5.45343 0.092572 0 1.56995 0</pose>
        <scale>1 1 1</scale>
        <link name='link'>
          <pose>-0.012537 5.45343 0.092572 0 1.56995 0</pose>
          <velocity>-0.0049 -0 -0.071258 0 -0.109222 0</velocity>
          <acceleration>-9.8 -0 0 0 1.46693 0</acceleration>
          <wrench>-49 -0 0 0 -0 0</wrench>
        </link>
      </model>
      <light name='sun'>
        <pose>0 0 10 0 -0 0</pose>
      </light>
    </state>
    <gui fullscreen='0'>
      <camera name='user_camera'>
        <pose>5.37994 -3.11858 8.65234 0 0.867644 2.2642</pose>
        <view_controller>orbit</view_controller>
        <projection_type>perspective</projection_type>
      </camera>
    </gui>
    <model name='robot'>
      <joint name='fixed' type='fixed'>
        <pose relative_to='__model__'>0 0 0 0 -0 0</pose>
        <parent>world</parent>
        <child>stationary_base</child>
      </joint>
      <link name='stationary_base'>
        <pose relative_to='fixed'>0 0 0 0 -0 0</pose>
        <inertial>
          <pose>0 0 0 0 -0 0</pose>
          <mass>10</mass>
          <inertia>
            <ixx>0.633333</ixx>
            <ixy>0</ixy>
            <ixz>0</ixz>
            <iyy>0.633333</iyy>
            <iyz>0</iyz>
            <izz>1.25</izz>
          </inertia>
        </inertial>
        <collision name='stationary_base_collision'>
          <pose>0 0 0 0 -0 0</pose>
          <geometry>
            <cylinder>
              <length>0.1</length>
              <radius>0.5</radius>
            </cylinder>
          </geometry>
          <max_contacts>10</max_contacts>
          <surface>
            <contact>
              <ode/>
            </contact>
            <bounce/>
            <friction>
              <torsional>
                <ode/>
              </torsional>
              <ode/>
            </friction>
          </surface>
        </collision>
        <visual name='stationary_base_visual'>
          <pose>0 0 0 0 -0 0</pose>
          <geometry>
            <cylinder>
              <length>0.1</length>
              <radius>0.5</radius>
            </cylinder>
          </geometry>
        </visual>
        <self_collide>0</self_collide>
        <enable_wind>0</enable_wind>
        <kinematic>0</kinematic>
      </link>
      <joint name='stationary_base_spin_base_joint' type='revolute'>
        <pose relative_to='stationary_base'>0 0 0.06 0 -0 0</pose>
        <parent>stationary_base</parent>
        <child>spin_base</child>
        <axis>
          <xyz>0 0 1</xyz>
          <limit>
            <lower>-3.14</lower>
            <upper>3.14</upper>
            <effort>100</effort>
            <velocity>2</velocity>
          </limit>
          <dynamics>
            <damping>10</damping>
            <friction>0.3</friction>
            <spring_reference>0</spring_reference>
            <spring_stiffness>0</spring_stiffness>
          </dynamics>
        </axis>
      </joint>
      <link name='spin_base'>
        <pose relative_to='stationary_base_spin_base_joint'>0 0 0 0 -0 0</pose>
        <inertial>
          <pose>0 0 0 0 -0 0</pose>
          <mass>2</mass>
          <inertia>
            <ixx>0.0816667</ixx>
            <ixy>0</ixy>
            <ixz>0</ixz>
            <iyy>0.0816667</iyy>
            <iyz>0</iyz>
            <izz>0.16</izz>
          </inertia>
        </inertial>
        <collision name='spin_base_collision'>
          <pose>0 0 0.05 0 -0 0</pose>
          <geometry>
            <cylinder>
              <length>0.1</length>
              <radius>0.4</radius>
            </cylinder>
          </geometry>
          <max_contacts>10</max_contacts>
          <surface>
            <contact>
              <ode/>
            </contact>
            <bounce/>
            <friction>
              <torsional>
                <ode/>
              </torsional>
              <ode/>
            </friction>
          </surface>
        </collision>
        <visual name='spin_base_visual'>
          <pose>0 0 0.05 0 -0 0</pose>
          <geometry>
            <cylinder>
              <length>0.1</length>
              <radius>0.4</radius>
            </cylinder>
          </geometry>
        </visual>
        <self_collide>0</self_collide>
        <enable_wind>0</enable_wind>
        <kinematic>0</kinematic>
      </link>
      <joint name='spin_base_arm1_joint' type='revolute'>
        <pose relative_to='spin_base'>0 0 0.2 0 -0 0</pose>
        <parent>spin_base</parent>
        <child>arm1</child>
        <axis>
          <xyz>0 1 0</xyz>
          <limit>
            <lower>-1.57</lower>
            <upper>1.57</upper>
            <effort>100</effort>
            <velocity>2</velocity>
          </limit>
          <dynamics>
            <damping>10</damping>
            <friction>0.3</friction>
            <spring_reference>0</spring_reference>
            <spring_stiffness>0</spring_stiffness>
          </dynamics>
        </axis>
      </joint>
      <link name='arm1'>
        <pose relative_to='spin_base_arm1_joint'>0 0 0 0 -0 0</pose>
        <inertial>
          <pose>0 0 0 0 -0 0</pose>
          <mass>0.5</mass>
          <inertia>
            <ixx>0.000833333</ixx>
            <ixy>0</ixy>
            <ixz>0</ixz>
            <iyy>0.0420833</iyy>
            <iyz>0</iyz>
            <izz>0.0420833</izz>
          </inertia>
        </inertial>
        <collision name='arm1_collision'>
          <pose>0 0 0.5 3.14159 1.57079 3.14159</pose>
          <geometry>
            <box>
              <size>1 0.1 0.1</size>
            </box>
          </geometry>
          <max_contacts>10</max_contacts>
          <surface>
            <contact>
              <ode/>
            </contact>
            <bounce/>
            <friction>
              <torsional>
                <ode/>
              </torsional>
              <ode/>
            </friction>
          </surface>
        </collision>
        <visual name='arm1_visual'>
          <pose>0 0 0.5 3.14159 1.57079 3.14159</pose>
          <geometry>
            <box>
              <size>1 0.1 0.1</size>
            </box>
          </geometry>
        </visual>
        <self_collide>0</self_collide>
        <enable_wind>0</enable_wind>
        <kinematic>0</kinematic>
      </link>
      <joint name='arm1_arm2_joint' type='revolute'>
        <pose relative_to='arm1'>0 0.05 1 0 -0 0</pose>
        <parent>arm1</parent>
        <child>arm2</child>
        <axis>
          <xyz>0 1 0</xyz>
          <limit>
            <lower>-3.14</lower>
            <upper>3.14</upper>
            <effort>100</effort>
            <velocity>2</velocity>
          </limit>
          <dynamics>
            <damping>10</damping>
            <friction>0.3</friction>
            <spring_reference>0</spring_reference>
            <spring_stiffness>0</spring_stiffness>
          </dynamics>
        </axis>
      </joint>
      <link name='arm2'>
        <pose relative_to='arm1_arm2_joint'>0 0 0 0 -0 0</pose>
        <inertial>
          <pose>0 0 0 0 -0 0</pose>
          <mass>0.5</mass>
          <inertia>
            <ixx>0.000833333</ixx>
            <ixy>0</ixy>
            <ixz>0</ixz>
            <iyy>0.0420833</iyy>
            <iyz>0</iyz>
            <izz>0.0420833</izz>
          </inertia>
        </inertial>
        <collision name='arm2_collision'>
          <pose>0 0.05 0.5 3.14159 1.57079 3.14159</pose>
          <geometry>
            <box>
              <size>1 0.1 0.1</size>
            </box>
          </geometry>
          <max_contacts>10</max_contacts>
          <surface>
            <contact>
              <ode/>
            </contact>
            <bounce/>
            <friction>
              <torsional>
                <ode/>
              </torsional>
              <ode/>
            </friction>
          </surface>
        </collision>
        <visual name='arm2_visual'>
          <pose>0 0.05 0.5 3.14159 1.57079 3.14159</pose>
          <geometry>
            <box>
              <size>1 0.1 0.1</size>
            </box>
          </geometry>
        </visual>
        <self_collide>0</self_collide>
        <enable_wind>0</enable_wind>
        <kinematic>0</kinematic>
      </link>
      <joint name='arm2_arm3_joint' type='revolute'>
        <pose relative_to='arm2'>0 0 1 0 -0 0</pose>
        <parent>arm2</parent>
        <child>arm3</child>
        <axis>
          <xyz>0 1 0</xyz>
          <limit>
            <lower>-3.14</lower>
            <upper>3.14</upper>
            <effort>100</effort>
            <velocity>2</velocity>
          </limit>
          <dynamics>
            <damping>10</damping>
            <friction>0.3</friction>
            <spring_reference>0</spring_reference>
            <spring_stiffness>0</spring_stiffness>
          </dynamics>
        </axis>
      </joint>
      <link name='arm3'>
        <pose relative_to='arm2_arm3_joint'>0 0 0 0 -0 0</pose>
        <inertial>
          <pose>0 0 0 0 -0 0</pose>
          <mass>0.5</mass>
          <inertia>
            <ixx>0.000833333</ixx>
            <ixy>0</ixy>
            <ixz>0</ixz>
            <iyy>0.0108333</iyy>
            <iyz>0</iyz>
            <izz>0.0108333</izz>
          </inertia>
        </inertial>
        <collision name='arm3_collision'>
          <pose>0 -0.05 0.25 3.14159 1.57079 3.14159</pose>
          <geometry>
            <box>
              <size>0.5 0.1 0.1</size>
            </box>
          </geometry>
          <max_contacts>10</max_contacts>
          <surface>
            <contact>
              <ode/>
            </contact>
            <bounce/>
            <friction>
              <torsional>
                <ode/>
              </torsional>
              <ode/>
            </friction>
          </surface>
        </collision>
        <visual name='arm3_visual'>
          <pose>0 -0.05 0.25 3.14159 1.57079 3.14159</pose>
          <geometry>
            <box>
              <size>0.5 0.1 0.1</size>
            </box>
          </geometry>
        </visual>
        <self_collide>0</self_collide>
        <enable_wind>0</enable_wind>
        <kinematic>0</kinematic>
      </link>
      <joint name='arm3_gripper1_joint' type='revolute'>
        <pose relative_to='arm3'>0 -0.05 0.5 0 -0 0</pose>
        <parent>arm3</parent>
        <child>gripper1</child>
        <axis>
          <xyz>-1 0 0</xyz>
          <limit>
            <lower>-3.14</lower>
            <upper>0</upper>
            <effort>100</effort>
            <velocity>2</velocity>
          </limit>
          <dynamics>
            <damping>10</damping>
            <friction>0.3</friction>
            <spring_reference>0</spring_reference>
            <spring_stiffness>0</spring_stiffness>
          </dynamics>
        </axis>
      </joint>
      <link name='gripper1'>
        <pose relative_to='arm3_gripper1_joint'>0 0 0 0 -0 0</pose>
        <inertial>
          <pose>0 0 0 0 -0 0</pose>
          <mass>0.1</mass>
          <inertia>
            <ixx>0.01</ixx>
            <ixy>0</ixy>
            <ixz>0</ixz>
            <iyy>0.01</iyy>
            <iyz>0</iyz>
            <izz>0.01</izz>
          </inertia>
        </inertial>
        <collision name='gripper1_collision'>
          <pose>-0.15 0 0 1.57 -0 1.57</pose>
          <geometry>
            <mesh>
              <scale>3 3 3</scale>
              <uri>/home/huynhmink/catkin_ws/src/hdm_robotarm01/mesh/gripper1.dae</uri>
            </mesh>
          </geometry>
          <max_contacts>10</max_contacts>
          <surface>
            <contact>
              <ode/>
            </contact>
            <bounce/>
            <friction>
              <torsional>
                <ode/>
              </torsional>
              <ode/>
            </friction>
          </surface>
        </collision>
        <visual name='gripper1_visual'>
          <pose>-0.15 0 0 1.57 -0 1.57</pose>
          <geometry>
            <mesh>
              <scale>3 3 3</scale>
              <uri>/home/huynhmink/catkin_ws/src/hdm_robotarm01/mesh/gripper1.dae</uri>
            </mesh>
          </geometry>
        </visual>
        <self_collide>0</self_collide>
        <enable_wind>0</enable_wind>
        <kinematic>0</kinematic>
      </link>
      <joint name='arm3_gripper2_joint' type='revolute'>
        <pose relative_to='arm3'>0 -0.05 0.5 0 -0 0</pose>
        <parent>arm3</parent>
        <child>gripper2</child>
        <axis>
          <xyz>1 0 0</xyz>
          <limit>
            <lower>-3.14</lower>
            <upper>0</upper>
            <effort>100</effort>
            <velocity>2</velocity>
          </limit>
          <dynamics>
            <damping>10</damping>
            <friction>0.3</friction>
            <spring_reference>0</spring_reference>
            <spring_stiffness>0</spring_stiffness>
          </dynamics>
        </axis>
      </joint>
      <link name='gripper2'>
        <pose relative_to='arm3_gripper2_joint'>0 0 0 0 -0 0</pose>
        <inertial>
          <pose>0 0 0 0 -0 0</pose>
          <mass>0.1</mass>
          <inertia>
            <ixx>0.01</ixx>
            <ixy>0</ixy>
            <ixz>0</ixz>
            <iyy>0.01</iyy>
            <iyz>0</iyz>
            <izz>0.01</izz>
          </inertia>
        </inertial>
        <collision name='gripper2_collision'>
          <pose>-0.15 0 0 1.57 -0 1.57</pose>
          <geometry>
            <mesh>
              <scale>3 3 3</scale>
              <uri>/home/huynhmink/catkin_ws/src/hdm_robotarm01/mesh/gripper2.dae</uri>
            </mesh>
          </geometry>
          <max_contacts>10</max_contacts>
          <surface>
            <contact>
              <ode/>
            </contact>
            <bounce/>
            <friction>
              <torsional>
                <ode/>
              </torsional>
              <ode/>
            </friction>
          </surface>
        </collision>
        <visual name='gripper2_visual'>
          <pose>-0.15 0 0 1.57 -0 1.57</pose>
          <geometry>
            <mesh>
              <scale>3 3 3</scale>
              <uri>/home/huynhmink/catkin_ws/src/hdm_robotarm01/mesh/gripper2.dae</uri>
            </mesh>
          </geometry>
        </visual>
        <self_collide>0</self_collide>
        <enable_wind>0</enable_wind>
        <kinematic>0</kinematic>
      </link>
      <static>0</static>
      <plugin name='gazebo_ros_control' filename='libgazebo_ros_control.so'>
        <robotNamespace>/</robotNamespace>
      </plugin>
      <pose>0 0 0.05 0 -0 0</pose>
    </model>
  </world>
</sdf>
