<?xml version="1.0" ?>
<!-- =================================================================================== -->
<!-- |    This document was autogenerated by xacro from model1.xacro                   | -->
<!-- |    EDITING THIS FILE BY HAND IS NOT RECOMMENDED                                 | -->
<!-- =================================================================================== -->
<robot name="hdm_robotarm01">
  <gazebo>
    <plugin filename="libgazebo_ros_control.so" name="gazebo_ros_control">
      <robotNamespace>/</robotNamespace>
    </plugin>
  </gazebo>
  <!-- stationary_base -->
  <gazebo reference="stationary_base">
    <gravity>true</gravity>
    <mu1>0.2</mu1>
    <mu2>0.2</mu2>
    <selfCollide>true</selfCollide>
  </gazebo>
  <!-- spin_base -->
  <gazebo reference="spin_base">
    <gravity>true</gravity>
    <mu1>0.2</mu1>
    <mu2>0.2</mu2>
    <selfCollide>true</selfCollide>
  </gazebo>
  <!-- arm1 -->
  <gazebo reference="arm1">
    <gravity>true</gravity>
    <mu1>0.2</mu1>
    <mu2>0.2</mu2>
    <selfCollide>true</selfCollide>
  </gazebo>
  <!-- arm2 -->
  <gazebo reference="arm2">
    <gravity>true</gravity>
    <mu1>0.2</mu1>
    <mu2>0.2</mu2>
    <selfCollide>true</selfCollide>
  </gazebo>
  <!-- arm3 -->
  <gazebo reference="arm3">
    <gravity>true</gravity>
    <mu1>0.2</mu1>
    <mu2>0.2</mu2>
    <selfCollide>true</selfCollide>
  </gazebo>
  <!-- gripper1 -->
  <gazebo reference="gripper1">
    <gravity>true</gravity>
    <mu1>0.2</mu1>
    <mu2>0.2</mu2>
    <selfCollide>true</selfCollide>
  </gazebo>
  <!-- gripper2 -->
  <gazebo reference="gripper2">
    <gravity>true</gravity>
    <mu1>0.2</mu1>
    <mu2>0.2</mu2>
    <selfCollide>true</selfCollide>
  </gazebo>
  <!-- fix model to world -->
  <link name="world"/>
  <joint name="fixed" type="fixed">
    <parent link="world"/>
    <child link="stationary_base"/>
  </joint>
  <link name="stationary_base">
    <visual>
      <geometry>
        <cylinder length="0.1" radius="0.5"/>
      </geometry>
      <origin rpy="0 0 0" xyz="0 0 0"/>
    </visual>
    <collision>
      <geometry>
        <cylinder length="0.1" radius="0.5"/>
      </geometry>
      <surface>
        <friction>
          <ode>
            <mu>0.5</mu>
            <mu2>0.5</mu2>
          </ode>
        </friction>
        <torsional>
          <coefficient>1</coefficient>
          <surface_radius>1</surface_radius>
          <use_patch_radius>false</use_patch_radius>
        </torsional>
      </surface>
      <origin rpy="0 0 0" xyz="0 0 0"/>
    </collision>
    <inertial>
      <mass value="10.0"/>
      <inertia ixx="0.6333333333333333" ixy="0.0" ixz="0.0" iyy="0.6333333333333333" iyz="0.0" izz="1.25"/>
    </inertial>
  </link>
  <link name="spin_base">
    <visual>
      <geometry>
        <cylinder length="0.1" radius="0.4"/>
      </geometry>
      <origin rpy="0 0 0" xyz="0 0 0.05"/>
    </visual>
    <collision>
      <geometry>
        <cylinder length="0.1" radius="0.4"/>
      </geometry>
      <surface>
        <friction>
          <ode>
            <mu>0.5</mu>
            <mu2>0.5</mu2>
          </ode>
        </friction>
        <torsional>
          <coefficient>1</coefficient>
          <surface_radius>1</surface_radius>
          <use_patch_radius>false</use_patch_radius>
        </torsional>
      </surface>
      <origin rpy="0 0 0" xyz="0 0 0.05"/>
    </collision>
    <inertial>
      <mass value="2.0"/>
      <inertia ixx="0.08166666666666668" ixy="0.0" ixz="0.0" iyy="0.08166666666666668" iyz="0.0" izz="0.16000000000000003"/>
    </inertial>
  </link>
  <joint name="stationary_base_spin_base_joint" type="revolute">
    <axis xyz="0 0 1"/>
    <limit effort="100" lower="-3.14" upper="3.14" velocity="2"/>
    <parent link="stationary_base"/>
    <child link="spin_base"/>
    <origin xyz="0 0 0.06"/>
    <dynamics damping="10.0" friction="0.3"/>
  </joint>
  <transmission name="stationary_base_spin_base_trans">
    <type>
		    	transmission_interface/SimpleTransmission
		    </type>
    <actuator name="stationary_base_spin_base_actuator">
      <hardwareInterface>
                    hardware_interface/EffortJointInterface
                </hardwareInterface>
      <mechanicalReduction>
		    		1
		    	</mechanicalReduction>
    </actuator>
    <joint name="stationary_base_spin_base_joint">
      <hardwareInterface>
                    hardware_interface/EffortJointInterface
                </hardwareInterface>
    </joint>
  </transmission>
  <link name="arm1">
    <visual>
      <geometry>
        <box size="1 0.1 0.1"/>
      </geometry>
      <origin rpy="0 1.57 0" xyz="0 0 0.5"/>
    </visual>
    <collision>
      <geometry>
        <box size="1 0.1 0.1"/>
      </geometry>
      <surface>
        <friction>
          <ode>
            <mu>0.5</mu>
            <mu2>0.5</mu2>
          </ode>
        </friction>
      </surface>
      <origin rpy="0 1.57 0" xyz="0 0 0.5"/>
    </collision>
    <inertial>
      <mass value="0.5"/>
      <inertia ixx="0.0008333333333333335" ixy="0.0" ixz="0.0" iyy="0.042083333333333334" iyz="0.0" izz="0.042083333333333334"/>
    </inertial>
  </link>
  <joint name="spin_base_arm1_joint" type="revolute">
    <axis xyz="0 1 0"/>
    <limit effort="100" lower="-1.57" upper="1.57" velocity="2"/>
    <parent link="spin_base"/>
    <child link="arm1"/>
    <origin xyz="0 0 0.2"/>
    <dynamics damping="10.0" friction="0.3"/>
  </joint>
  <transmission name="spin_base_arm1_trans">
    <type>
		    	transmission_interface/SimpleTransmission
		    </type>
    <actuator name="spin_base_arm1_actuator">
      <hardwareInterface>
                    hardware_interface/EffortJointInterface
                </hardwareInterface>
      <mechanicalReduction>
		    		1
		    	</mechanicalReduction>
    </actuator>
    <joint name="spin_base_arm1_joint">
      <hardwareInterface>
                    hardware_interface/EffortJointInterface
                </hardwareInterface>
    </joint>
  </transmission>
  <link name="arm2">
    <visual>
      <geometry>
        <box size="1 0.1 0.1"/>
      </geometry>
      <origin rpy="0 1.57 0" xyz="0 0.05 0.5"/>
    </visual>
    <collision>
      <geometry>
        <box size="1 0.1 0.1"/>
      </geometry>
      <surface>
        <friction>
          <ode>
            <mu>0.5</mu>
            <mu2>0.5</mu2>
          </ode>
        </friction>
      </surface>
      <origin rpy="0 1.57 0" xyz="0 0.05 0.5"/>
    </collision>
    <inertial>
      <mass value="0.5"/>
      <inertia ixx="0.0008333333333333335" ixy="0.0" ixz="0.0" iyy="0.042083333333333334" iyz="0.0" izz="0.042083333333333334"/>
    </inertial>
  </link>
  <joint name="arm1_arm2_joint" type="revolute">
    <axis xyz="0 1 0"/>
    <limit effort="100" lower="-3.14" upper="3.14" velocity="2"/>
    <parent link="arm1"/>
    <child link="arm2"/>
    <origin xyz="0 0.05 1"/>
    <dynamics damping="10.0" friction="0.3"/>
  </joint>
  <transmission name="arm1_arm2_trans">
    <type>
		    	transmission_interface/SimpleTransmission
		    </type>
    <actuator name="arm1_arm2_actuator">
      <hardwareInterface>
                    hardware_interface/EffortJointInterface
                </hardwareInterface>
      <mechanicalReduction>
		    		1
		    	</mechanicalReduction>
    </actuator>
    <joint name="arm1_arm2_joint">
      <hardwareInterface>
                    hardware_interface/EffortJointInterface
                </hardwareInterface>
    </joint>
  </transmission>
  <link name="arm3">
    <visual>
      <geometry>
        <box size="0.5 0.1 0.1"/>
      </geometry>
      <origin rpy="0 1.57 0" xyz="0 -0.05 0.25"/>
    </visual>
    <collision>
      <geometry>
        <box size="0.5 0.1 0.1"/>
      </geometry>
      <surface>
        <friction>
          <ode>
            <mu>0.5</mu>
            <mu2>0.5</mu2>
          </ode>
        </friction>
      </surface>
      <origin rpy="0 1.57 0" xyz="0 -0.05 0.25"/>
    </collision>
    <inertial>
      <mass value="0.5"/>
      <inertia ixx="0.0008333333333333335" ixy="0.0" ixz="0.0" iyy="0.010833333333333334" iyz="0.0" izz="0.010833333333333334"/>
    </inertial>
  </link>
  <joint name="arm2_arm3_joint" type="revolute">
    <axis xyz="0 1 0"/>
    <limit effort="100" lower="-3.14" upper="3.14" velocity="2"/>
    <parent link="arm2"/>
    <child link="arm3"/>
    <origin xyz="0 0 1"/>
    <dynamics damping="10.0" friction="0.3"/>
  </joint>
  <transmission name="arm2_arm3_trans">
    <type>
		    	transmission_interface/SimpleTransmission
		    </type>
    <actuator name="arm2_arm3_actuator">
      <hardwareInterface>
                    hardware_interface/EffortJointInterface
                </hardwareInterface>
      <mechanicalReduction>
		    		1
		    	</mechanicalReduction>
    </actuator>
    <joint name="arm2_arm3_joint">
      <hardwareInterface>
                    hardware_interface/EffortJointInterface
                </hardwareInterface>
    </joint>
  </transmission>
  <link name="gripper1">
    <visual>
      <geometry>
        <mesh filename="package://hdm_robotarm01/mesh/gripper1.dae" scale="3 3 3"/>
      </geometry>
      <origin rpy="1.57 0 1.57" xyz="-0.15 0 0"/>
    </visual>
    <collision>
      <geometry>
        <mesh filename="package://hdm_robotarm01/mesh/gripper1.dae" scale="3 3 3"/>
      </geometry>
      <surface>
        <friction>
          <ode>
            <mu>0.8</mu>
            <mu2>0.8</mu2>
          </ode>
        </friction>
      </surface>
      <origin rpy="1.57 0 1.57" xyz="-0.15 0 0"/>
    </collision>
    <inertial>
      <mass value="0.1"/>
      <inertia ixx="0.01" ixy="0.0" ixz="0.0" iyy="0.01" iyz="0.0" izz="0.01"/>
    </inertial>
  </link>
  <joint name="arm3_gripper1_joint" type="revolute">
    <axis xyz="-1 0 0"/>
    <limit effort="100" lower="-3.14" upper="0" velocity="2"/>
    <parent link="arm3"/>
    <child link="gripper1"/>
    <origin xyz="0 -0.05 0.5"/>
    <dynamics damping="10.0" friction="0.3"/>
  </joint>
  <transmission name="arm3_gripper1_trans">
    <type>
		    	transmission_interface/SimpleTransmission
		    </type>
    <actuator name="arm3_gripper1_actuator">
      <hardwareInterface>
                    hardware_interface/EffortJointInterface
                </hardwareInterface>
      <mechanicalReduction>
		    		1
		    	</mechanicalReduction>
    </actuator>
    <joint name="arm3_gripper1_joint">
      <hardwareInterface>
                    hardware_interface/EffortJointInterface
                </hardwareInterface>
    </joint>
  </transmission>
  <link name="gripper2">
    <visual>
      <geometry>
        <mesh filename="package://hdm_robotarm01/mesh/gripper2.dae" scale="3 3 3"/>
      </geometry>
      <origin rpy="1.57 0 1.57" xyz="-0.15 0 0"/>
    </visual>
    <collision>
      <geometry>
        <mesh filename="package://hdm_robotarm01/mesh/gripper2.dae" scale="3 3 3"/>
      </geometry>
      <surface>
        <friction>
          <ode>
            <mu>0.8</mu>
            <mu2>0.8</mu2>
          </ode>
        </friction>
      </surface>
      <origin rpy="1.57 0 1.57" xyz="-0.15 0 0"/>
    </collision>
    <inertial>
      <mass value="0.1"/>
      <inertia ixx="0.01" ixy="0.0" ixz="0.0" iyy="0.01" iyz="0.0" izz="0.01"/>
    </inertial>
  </link>
  <joint name="arm3_gripper2_joint" type="revolute">
    <axis xyz="1 0 0"/>
    <limit effort="100" lower="-3.14" upper="0" velocity="2"/>
    <parent link="arm3"/>
    <child link="gripper2"/>
    <origin xyz="0 -0.05 0.5"/>
    <dynamics damping="10.0" friction="0.3"/>
  </joint>
  <transmission name="arm3_gripper2_trans">
    <type>
		    	transmission_interface/SimpleTransmission
		    </type>
    <actuator name="arm3_gripper2_actuator">
      <hardwareInterface>
                    hardware_interface/EffortJointInterface
                </hardwareInterface>
      <mechanicalReduction>
		    		1
		    	</mechanicalReduction>
    </actuator>
    <joint name="arm3_gripper2_joint">
      <hardwareInterface>
                    hardware_interface/EffortJointInterface
                </hardwareInterface>
    </joint>
  </transmission>
</robot>

